<?xml version="1.0"?>
<robot xmlns:xacro="http://www.ros.org/wiki/xacro" name="agv">

    <xacro:arg name="is_ignition" default="true" /> 

    <!-- Include Gazebo Parameters-->
    <xacro:include filename="$(find agv_description)/urdf/agv_gazebo.xacro"/>
    
    <!-- ROS 2 Control -->
    <xacro:include filename="$(find agv_description)/urdf/agv_ros2_control.xacro"/>

    <link name="base_footprint"/>

    
    <link name="base_link">
        <inertial>
            <origin xyz="0.0 0.0 0.904348"/>
            <!-- <mass value="3.0"/>
            <inertia ixx="0.02" ixy="0" ixz="0" iyy="0.0325" iyz="0" izz="0.0325" /> -->
            <mass value="8.2573504e-01"/>
            <inertia ixx="2.2124416e-02" ixy="-1.2294101e-04" ixz="3.4938785e-04" iyy="2.1193702e-02" iyz="-5.0120904e-05" izz="2.0064271e-02"/>
        </inertial>
        <visual>
            <origin rpy="0.0 0.0 0.0" xyz="0.0 0.0 0.0"/>
            <geometry>
                <mesh filename="package://agv_description/meshes/base_link.stl" scale="0.001 0.001 0.001"/>
            </geometry>            
        </visual>
        <collision>
            <origin rpy="0.0 0.0 0.0" xyz="0.0 0.0 0.0"/>
            <geometry>
                <mesh filename="package://agv_description/meshes/base_link.stl" scale="0.001 0.001 0.001"/>
            </geometry>
        </collision>
    </link>

    <joint name="base_joint" type="fixed">
        <parent link="base_footprint"/>
        <child link="base_link"/>   
        <origin rpy="0.0 0.0 0.0" xyz="0.0 0.0 0.315"/>
    </joint>


    <link name="wheel_right_link">
        <inertial>
            <origin xyz="0.0 -0.014 0.0" rpy="0.0 0.0 0.0"/>
            <!-- <mass value="0.0530086090966721"/>
            <inertia ixx="0.00000304" ixy="0.0" ixz="0.0" iyy="0.0000052" iyz="0.0" izz="0.00000304"/> -->
            <mass value="0.0530086090966721"/>
            <inertia ixx="1.88176298336665E-05" ixy="-4.8444933029987E-10" ixz="1.88163708851143E-08" iyy="3.11510738647764E-05" iyz="-6.93560663069607E-11" izz="1.8801969558182E-05"/>
        </inertial>
        
        <visual>
            <origin rpy="1.570796 0.0 0.0" xyz="0.0 0.0 0.0"/>
            <geometry>
                <mesh filename="package://agv_description/meshes/wheel_right_link.stl" scale="0.001 0.001 0.001"/>
            </geometry>
        </visual>
        <collision>
            <origin rpy="1.570796 0.0 0.0" xyz="0.0 0.0 0.0"/>
            <geometry>
                <mesh filename="package://agv_description/meshes/wheel_right_link.stl" scale="0.001 0.001 0.001"/>
                <!-- <sphere radius="0.300"/> -->
            </geometry>
        </collision>
    </link>
    
    <joint name="wheel_right_joint" type="continuous">
        <parent link="base_link"/>
        <child link="wheel_right_link"/>
        <axis xyz="0.0 1.0 0.0"/>
        <origin rpy="0.0 0.0 -1.570796" xyz="-1.55 1.22 0.0"/>
    </joint>


    <link name="wheel_left_link">
        <inertial>
            <origin xyz="0.0 0.014 0.0" rpy="0.0 0.0 0.0"/>
            <!-- <mass value="0.0530086090966721"/>
            <inertia ixx="0.00000304" ixy="0.0" ixz="0.0" iyy="0.0000052" iyz="0.0" izz="0.00000304"/> -->
            <mass value="0.0530086043217644"/>
            <inertia ixx="1.8792911368909E-05" ixy="3.31256392204584E-10" ixz="-1.14082001662767E-08" iyy="3.11510738759073E-05" iyz="-3.60499245082192E-10" izz="1.88266886146847E-05"/>
        </inertial>

        <visual>
            <origin rpy="-1.570796 0.0 0.0" xyz="0.0 0.0 0.0"/>
            <geometry>
                <mesh filename="package://agv_description/meshes/wheel_right_link.stl" scale="0.001 0.001 0.001"/>
            </geometry>
        </visual>
        <collision>
            <origin rpy="1.570796 0.0 0.0" xyz="0.0 0.0 0.0"/>
            <geometry>
                <mesh filename="package://agv_description/meshes/wheel_right_link.stl" scale="0.001 0.001 0.001"/>
                 <!-- <sphere radius="0.300"/> -->
            </geometry>
        </collision>
    </link>
    <joint name="wheel_left_joint" type="continuous">
        <parent link="base_link"/>
        <child link="wheel_left_link"/>
        <axis xyz="0.0 1.0 0.0"/>
        <origin rpy="0.0 0.0 -1.570796" xyz="1.55 1.22 0.0"/>
    </joint>



    <link name="caster_link">

        <inertial>
            <origin xyz="0.0 0.0 0.0" rpy="0.0 0.0 0.0"/>
            <!-- <mass value="0.1"/>
            <inertia ixx="0.0001" ixy="0.0001" ixz="0.0001" iyy="0.0001" iyz="0.0001" izz="0.0001"/> -->
            <mass value="1.44379265037903E-06"/>
            <inertia ixx="7.23075276010246E-11" ixy="-6.10956883467859E-16" ixz="2.22849693525031E-15" iyy="3.8713793085917E-11" iyz="2.93909858781952E-15" izz="1.00967486676306E-10"/>
        </inertial>
   
        <visual>
            <origin rpy="0.0 0.0 0.0" xyz="0.0 0.0 0.0"/>
            <geometry>
                <mesh filename="package://agv_description/meshes/caster_link.stl" scale="0.001 0.001 0.001"/>
            </geometry>
        </visual>
        <collision>
            <origin xyz="0.0 0.0 0.0"/>
            <geometry>
                <mesh filename="package://agv_description/meshes/caster_link.stl" scale="0.001 0.001 0.001"/>
            </geometry>
        </collision>
    </link>
    <joint name="caster_joint" type="fixed">
        <parent link="base_link"/>
        <child link="caster_link"/>
        <axis xyz="0.0 0.0 0.0"/>
        <origin rpy="0.0 0.0 0.0" xyz="0.0 -0.95 -0.261"/>
    </joint>
</robot>