<?xml version="1.0"?>
<robot xmlns="http://www.ros.org/wiki/xacro" name="agv">
    <link name="base_footprint"/>
    <link name="base_link">
        <visual>
            <origin rpy="0.0 0.0 0.0" xyz="0.0 0.0 0.0"/>

            <geometry>
                <mesh filename="package://agv_description/meshes/base_link.stl" scale="0.001 0.001 0.001"/>
            </geometry>            
        </visual>
    </link>
    <joint name="base_joint" type="fixed">
        <parent link="base_footprint"/>
        <child link="base_link"/>   
        <origin rpy="0.0 0.0 0.0" xyz="0.0 0.0 0.315"/>
    </joint>
    <link name="wheel_right_link">
        <visual>
            <origin rpy="1.57 0.0 -1.57" xyz="-1.56 1.3 0.0"/>
            <geometry>
                <mesh filename="package://agv_description/meshes/wheel_right_link.stl" scale="0.001 0.001 0.001"/>
            </geometry>
        </visual>
    </link>
    
    <joint name="wheel_right_joint" type="continuous">
        <parent link="base_link"/>
        <child link="wheel_right_link"/>
        <axis xyz="0.0 1.0 0.0"/>
        <origin rpy="0.0 0.0 0.0" xyz="0.0 -0.07 0.0"/>
    </joint>
    <link name="wheel_left_link">
        <visual>
            
            <origin rpy="-1.57 0.0 1.57" xyz="1.8 1.3 0.0"/>
            <geometry>
                <mesh filename="package://agv_description/meshes/wheel_right_link.stl" scale="0.001 0.001 0.001"/>
            </geometry>
        </visual>
    </link>
    <joint name="wheel_left_joint" type="continuous">
        <parent link="base_link"/>
        <child link="wheel_left_link"/>
        <axis xyz="0.0 1.0 0.0"/>
        <origin rpy="0.0 0.0 0.0" xyz="0.0 0.07 0.0"/>
    </joint>
</robot>